Workbook

Sheet Individual Data
A1: Original Dataset | D1: Rolled Up Data
A5: x | B5: N_X | D5: x | E5: n_x
A6: 0 | B6: 975 | D6: 0 | E6: 975
A7: 1 | B7: 127 | D7: 1 | E7: 127
A8: 2 | B8: 225 | D8: 2 | E8: 225
A9: 3 | B9: 91 | D9: 3 | E9: 91
A10: 4 | B10: 97 | D10: 4 | E10: 97
A11: 5 | B11: 61 | D11: 5 | E11: 61
A12: 6 | B12: 47 | D12: 6 | E12: 47
A13: 7 | B13: 25 | D13: 7 | E13: 25
A14: 8 | B14: 38 | D14: 8 | E14: 38
A15: 9 | B15: 39 | D15: 9 | E15: 39
A16: 10 | B16: 26 | D16: 10 | E16: 26
A17: 11 | B17: 19 | D17: 11 | E17: 19
... A25: 19 | B25: 17 | D25: 19 | E25: 17
A26: 20 | B26: 4 | D26: 20+ | E26: =1980 - SUM(E6:E25) -> 94
A27: 21 | B27: 7
A28: 22 | B28: 9
A29: 23 | B29: 6
A30: 24 | B30: 8 | D30: Total | E30: =SUM(E6:E26) -> 1980
A31: 25 | B31: 6
A32: 26 | B32: 3
A33: 27 | B33: 9
A34: 28 | B34: 5
A35: 29 | B35: 4
A36: 30 | B36: 7
A37: 31 | B37: 5
A38: 32 | B38: 3
A39: 33 | B39: 3
A40: 34 | B40: 2
A41: 35 | B41: 2
A42: 36 | B42: 3
... A48: 42 | B48: 0
A51: Total | B51: =SUM(B6:B48) -> 1980

Sheet NBD fit (bad)
A1: r | B1: 1
A2: alpha | B2: 1
A3: LL | B3: =SUM(D6:D48) -> -6551.6272
A5: x | B5: N_X | C5: P(X=x) | D5: LL | E5: predicted | F5: chisq
A6: 0 | B6: 975 | C6: =(B2/(B2+1))^B1 -> 0.5 | D6: =B6*LN(C6) -> -675.8185 | E6: =1980*C6 -> 990 | F6: =(E6-B6)^2/B6 -> 0.23076923
A7: 1 | B7: 127 | C7: =C6*($B$1+A6)/(A7*($B$2+1)) -> 0.25 | D7: =B7*LN(C7) -> -176.05938 | E7: =1980*C7 -> 495 | F7: =(E7-B7)^2/B7 -> 1066.3307
A8: 2 | B8: 225 | C8: =C7*($B$1+A7)/(A8*($B$2+1)) -> 0.125 | D8: =B8*LN(C8) -> -467.87435 | E8: =1980*C8 -> 247.5 | F8: =(E8-B8)^2/B8 -> 2.25
A9: 3 | B9: 91 | C9: =C8*($B$1+A8)/(A9*($B$2+1)) -> 0.0625 | D9: =B9*LN(C9) -> -252.30557 | E9: =1980*C9 -> 123.75 | F9: =(E9-B9)^2/B9 -> 11.786401
A10: 4 | B10: 97 | C10: =C9*($B$1+A9)/(A10*($B$2+1)) -> 0.03125 | D10: =B10*LN(C10) -> -336.17638 | E10: =1980*C10 -> 61.875 | F10: =(E10-B10)^2/B10 -> 12.719233
A11: 5 | B11: 61 | C11: =C10*($B$1+A10)/(A11*($B$2+1)) -> 0.015625 | D11: =B11*LN(C11) -> -253.69187 | E11: =1980*C11 -> 30.9375 | F11: =(E11-B11)^2/B11 -> 14.815638
A12: 6 | B12: 47 | C12: =C11*($B$1+A11)/(A12*($B$2+1)) -> 0.0078125 | D12: =B12*LN(C12) -> -228.04542 | E12: =1980*C12 -> 15.46875 | F12: =(E12-B12)^2/B12 -> 21.153611
A13: 7 | B13: 25 | C13: =C12*($B$1+A12)/(A13*($B$2+1)) -> 0.00390625 | D13: =B13*LN(C13) -> -138.62944 | E13: =1980*C13 -> 7.734375 | F13: =(E13-B13)^2/B13 -> 11.924072
A14: 8 | B14: 38 | C14: =C13*($B$1+A13)/(A14*($B$2+1)) -> 0.001953125 | D14: =B14*LN(C14) -> -237.05634 | E14: =1980*C14 -> 3.8671875 | F14: =(E14-B14)^2/B14 -> 30.659181
A15: 9 | B15: 39 | C15: =C14*($B$1+A14)/(A15*($B$2+1)) -> 0.0009765625 | D15: =B15*LN(C15) -> -270.3274
A16: 10 | B16: 26 | C16: =C15*($B$1+A15)/(A16*($B$2+1)) -> 0.00048828125 | D16: =B16*LN(C16) -> -198.24009
A17: 11 | B17: 19 | C17: =C16*($B$1+A16)/(A17*($B$2+1)) -> 0.00024414062 | D17: =B17*LN(C17) -> -158.03756
A18: 12 | B18: 23 | C18: =C17*($B$1+A17)/(A18*($B$2+1)) -> 0.00012207031 | D18: =B18*LN(C18) -> -207.25101
A19: 13 | B19: 17 | C19: =C18*($B$1+A18)/(A19*($B$2+1)) -> 6.1035156e-05 | D19: =B19*LN(C19) -> -164.96903
A20: 14 | B20: 13 | C20: =C19*($B$1+A19)/(A20*($B$2+1)) -> 3.0517578e-05 | D20: =B20*LN(C20) -> -135.1637
A21: 15 | B21: 11 | C21: =C20*($B$1+A20)/(A21*($B$2+1)) -> 1.5258789e-05 | D21: =B21*LN(C21) -> -121.9939
A22: 16 | B22: 15 | C22: =C21*($B$1+A21)/(A22*($B$2+1)) -> 7.6293945e-06 | D22: =B22*LN(C22) -> -176.75253
A23: 17 | B23: 11 | C23: =C22*($B$1+A22)/(A23*($B$2+1)) -> 3.8146973e-06 | D23: =B23*LN(C23) -> -137.24314
A24: 18 | B24: 9 | C24: =C23*($B$1+A23)/(A24*($B$2+1)) -> 1.9073486e-06 | D24: =B24*LN(C24) -> -118.52817
A25: 19 | B25: 17 | C25: =C24*($B$1+A24)/(A25*($B$2+1)) -> 9.5367432e-07 | D25: =B25*LN(C25) -> -235.67004
A26: 20 | B26: 4 | C26: =C25*($B$1+A25)/(A26*($B$2+1)) -> 4.7683716e-07 | D26: =B26*LN(C26) -> -58.224363
... A36: 30 | B36: 7 | C36: =C35*($B$1+A35)/(A36*($B$2+1)) -> 4.6566129e-10 | D36: =B36*LN(C36) -> -150.41294
A37: 31 | B37: 5 | C37: =C36*($B$1+A36)/(A37*($B$2+1)) -> 2.3283064e-10 | D37: =B37*LN(C37) -> -110.90355 | F37: chisq | G37: =SUM(F6:F14) -> 1171.8696
A38: 32 | B38: 3 | C38: =C37*($B$1+A37)/(A38*($B$2+1)) -> 1.1641532e-10 | D38: =B38*LN(C38) -> -68.621571 | F38: df | G38: =9 - 2- 1 -> 6
A39: 33 | B39: 3 | C39: =C38*($B$1+A38)/(A39*($B$2+1)) -> 5.8207661e-11 | D39: =B39*LN(C39) -> -70.701012 | F39: pvalue | G39: =_xlfn.CHISQ.DIST.RT(G37,G38) -> 5.8599969e-250
A40: 34 | B40: 2 | C40: =C39*($B$1+A39)/(A40*($B$2+1)) -> 2.910383e-11 | D40: =B40*LN(C40) -> -48.520303
A41: 35 | B41: 2 | C41: =C40*($B$1+A40)/(A41*($B$2+1)) -> 1.4551915e-11 | D41: =B41*LN(C41) -> -49.906597
A42: 36 | B42: 3 | C42: =C41*($B$1+A41)/(A42*($B$2+1)) -> 7.2759576e-12 | D42: =B42*LN(C42) -> -76.939337
A43: 37 | B43: 4 | C43: =C42*($B$1+A42)/(A43*($B$2+1)) -> 3.6379788e-12 | D43: =B43*LN(C43) -> -105.35837
A44: 38 | B44: 2 | C44: =C43*($B$1+A43)/(A44*($B$2+1)) -> 1.8189894e-12 | D44: =B44*LN(C44) -> -54.06548
A45: 39 | B45: 0 | C45: =C44*($B$1+A44)/(A45*($B$2+1)) -> 9.094947e-13 | D45: =B45*LN(C45) -> 0
A46: 40 | B46: 2 | C46: =C45*($B$1+A45)/(A46*($B$2+1)) -> 4.5474735e-13 | D46: =B46*LN(C46) -> -56.838069
A47: 41 | B47: 0 | C47: =C46*($B$1+A46)/(A47*($B$2+1)) -> 2.2737368e-13 | D47: =B47*LN(C47) -> 0
A48: 42 | B48: 0 | C48: =C47*($B$1+A47)/(A48*($B$2+1)) -> 1.1368684e-13 | D48: =B48*LN(C48) -> 0

Sheet zerospike
A1: r | B1: 0.55817735
A2: alpha | B2: 0.10215842
A3: spike@0 | B3: 0.30932088
A4: LL | B4: =SUM(E7:E49) -> -4302.6273
A6: x | B6: N_X | C6: P(X = x) | D6: spike | E6: LL | H6: x | I6: n_x | J6: P(X = x) | K6: predicted | L6: chisq
A7: 0 | B7: 975 | C7: =(B2/(B2+1))^B1 -> 0.26510604 | D7: =$B$3 + (1-$B$3) * C7 -> 0.49242409 | E7: =B7* LN(D7) -> -690.7046 | H7: 0 | I7: 975 | J7: =D7 -> 0.49242409 | K7: =J7*1980 -> 974.99969 | L7: =(K7-I7)^2/I7 -> 9.7912412e-11
A8: 1 | B8: 127 | C8: =C7*($B$1+A7)/(A8*($B$2+1)) -> 0.13426036 | D8: =(1-$B$3) *C8 -> 0.09273083 | E8: =B8* LN(D8) -> -302.01289 | H8: 1 | I8: 127 | J8: =D8 -> 0.09273083 | K8: =J8*1980 -> 183.60704 | L8: =(K8-I8)^2/I8 -> 25.23116
A9: 2 | B9: 225 | C9: =C8*($B$1+A8)/(A9*($B$2+1)) -> 0.094905348 | D9: =(1-$B$3) *C9 -> 0.065549142 | E9: =B9* LN(D9) -> -613.11491 | H9: 2 | I9: 225 | J9: =D9 -> 0.065549142 | K9: =J9*1980 -> 129.7873 | L9: =(K9-I9)^2/I9 -> 40.290924
A10: 3 | B10: 91 | C10: =C9*($B$1+A9)/(A10*($B$2+1)) -> 0.073427046 | D10: =(1-$B$3) *C10 -> 0.050714528 | E10: =B10* LN(D10) -> -271.3204 | H10: 3 | I10: 91 | J10: =D10 -> 0.050714528 | K10: =J10*1980 -> 100.41476 | L10: =(K10-I10)^2/I10 -> 0.97404169
A11: 4 | B11: 97 | C11: =C10*($B$1+A10)/(A11*($B$2+1)) -> 0.059262454 | D11: =(1-$B$3) *C11 -> 0.04093134 | E11: =B11* LN(D11) -> -309.99835 | H11: 4 | I11: 97 | J11: =D11 -> 0.04093134 | K11: =J11*1980 -> 81.044053 | L11: =(K11-I11)^2/I11 -> 2.6246624
A12: 5 | B12: 61 | C12: =C11*($B$1+A11)/(A12*($B$2+1)) -> 0.049018139 | D12: =(1-$B$3) *C12 -> 0.033855805 | E12: =B12* LN(D12) -> -206.52433 | H12: 5 | I12: 61 | J12: =D12 -> 0.033855805 | K12: =J12*1980 -> 67.034495 | L12: =(K12-I12)^2/I12 -> 0.5969693
A13: 6 | B13: 47 | C13: =C12*($B$1+A12)/(A13*($B$2+1)) -> 0.04119969 | D13: =(1-$B$3) *C13 -> 0.028455766 | E13: =B13* LN(D13) -> -167.29201 | H13: 6 | I13: 47 | J13: =D13 -> 0.028455766 | K13: =J13*1980 -> 56.342416 | L13: =(K13-I13)^2/I13 -> 1.857037
A14: 7 | B14: 25 | C14: =C13*($B$1+A13)/(A14*($B$2+1)) -> 0.035021524 | D14: =(1-$B$3) *C14 -> 0.024188635 | E14: =B14* LN(D14) -> -93.046809 | H14: 7 | I14: 25 | J14: =D14 -> 0.024188635 | K14: =J14*1980 -> 47.893498 | L14: =(K14-I14)^2/I14 -> 20.96449
A15: 8 | B15: 38 | C15: =C14*($B$1+A14)/(A15*($B$2+1)) -> 0.030020513 | D15: =(1-$B$3) *C15 -> 0.020734541 | E15: =B15* LN(D15) -> -147.28626 | H15: 8 | I15: 38 | J15: =D15 -> 0.020734541 | K15: =J15*1980 -> 41.054392 | L15: =(K15-I15)^2/I15 -> 0.24550819
A16: 9 | B16: 39 | C16: =C15*($B$1+A15)/(A16*($B$2+1)) -> 0.025900781 | D16: =(1-$B$3) *C16 -> 0.017889129 | E16: =B16* LN(D16) -> -156.91892 | H16: 9 | I16: 39 | J16: =D16 -> 0.017889129 | K16: =J16*1980 -> 35.420474 | L16: =(K16-I16)^2/I16 -> 0.32853854
A17: 10 | B17: 26 | C17: =C16*($B$1+A16)/(A17*($B$2+1)) -> 0.022461767 | D17: =(1-$B$3) *C17 -> 0.015513873 | E17: =B17* LN(D17) -> -108.31654 | H17: 10 | I17: 26 | J17: =D17 -> 0.015513873 | K17: =J17*1980 -> 30.717469 | L17: =(K17-I17)^2/I17 -> 0.855943
A18: 11 | B18: 19 | C18: =C17*($B$1+A17)/(A18*($B$2+1)) -> 0.01956123 | D18: =(1-$B$3) *C18 -> 0.013510533 | E18: =B18* LN(D18) -> -81.781428 | H18: 11 | I18: 19 | J18: =D18 -> 0.013510533 | K18: =J18*1980 -> 26.750856 | L18: =(K18-I18)^2/I18 -> 3.1618823
A19: 12 | B19: 23 | C19: =C18*($B$1+A18)/(A19*($B$2+1)) -> 0.017094651 | D19: =(1-$B$3) *C19 -> 0.011806919 | E19: =B19* LN(D19) -> -102.0986 | H19: 12 | I19: 23 | J19: =D19 -> 0.011806919 | K19: =J19*1980 -> 23.377699 | L19: =(K19-I19)^2/I19 -> 0.0062024569
... A26: 19 | B26: 17 | C26: =C25*($B$1+A25)/(A26*($B$2+1)) -> 0.0070894957 | D26: =(1-$B$3) *C26 -> 0.0048965667 | E26: =B26* LN(D26) -> -90.426757 | H26: 19 | I26: 17 | J26: =D26 -> 0.0048965667 | K26: =J26*1980 -> 9.695202 | L26: =(K26-I26)^2/I26 -> 3.1388279
A27: 20 | B27: 4 | C27: =C26*($B$1+A26)/(A27*($B$2+1)) -> 0.006290276 | D27: =(1-$B$3) *C27 -> 0.0043445623 | E27: =B27* LN(D27) -> -21.755321 | H27: 20+ | I27: 94 | J27: =1-SUM(J7:J26) -> 0.040517179 | K27: =J27*1980 -> 80.224014 | L27: =(K27-I27)^2/I27 -> 2.0189128
A28: 21 | B28: 7 | C28: =C27*($B$1+A27)/(A28*($B$2+1)) -> 0.0055871585 | D28: =(1-$B$3) *C28 -> 0.0038589337 | E28: =B28* LN(D28) -> -38.901551
A29: 22 | B29: 9 | C29: =C28*($B$1+A28)/(A29*($B$2+1)) -> 0.0049674823 | D29: =(1-$B$3) *C29 -> 0.0034309363 | E29: =B29* LN(D29) -> -51.074299 | I29: chisq | J29: =SUM(L7:L27) -> 107.73476
A30: 23 | B30: 6 | C30: =C29*($B$1+A29)/(A30*($B$2+1)) -> 0.0044204703 | D30: =(1-$B$3) *C30 -> 0.0030531265 | E30: =B30* LN(D30) -> -34.749535 | I30: df | J30: =21 - 3 - 1 -> 17
A31: 24 | B31: 8 | C31: =C30*($B$1+A30)/(A31*($B$2+1)) -> 0.0039369046 | D31: =(1-$B$3) *C31 -> 0.0027191378 | E31: =B31* LN(D31) -> -47.259523 | I31: pvalue | J31: =_xlfn.CHISQ.DIST.RT(J29,J30) -> 3.2145133e-15
A32: 25 | B32: 6 | C32: =C31*($B$1+A31)/(A32*($B$2+1)) -> 0.0035088677 | D32: =(1-$B$3) *C32 -> 0.0024235017 | E32: =B32* LN(D32) -> -36.135251
A33: 26 | B33: 3 | C33: =C32*($B$1+A32)/(A33*($B$2+1)) -> 0.0031295327 | D33: =(1-$B$3) *C33 -> 0.0021615029 | E33: =B33* LN(D33) -> -18.410854 | I33: LRT vs Original
A34: 27 | B34: 9 | C34: =C33*($B$1+A33)/(A34*($B$2+1)) -> 0.0027929938 | D34: =(1-$B$3) *C34 -> 0.0019290625 | E34: =B34* LN(D34) -> -56.25649 | I34: chisq | J34: =2 * (B4 - 'NBD fit (bad)'!B3) -> 4497.9996
A35: 28 | B35: 5 | C35: =C34*($B$1+A34)/(A35*($B$2+1)) -> 0.0024941261 | D35: =(1-$B$3) *C35 -> 0.0017226409 | E35: =B35* LN(D35) -> -31.819484 | I35: df | J35: =3 - 2 -> 1
A36: 29 | B36: 4 | C36: =C35*($B$1+A35)/(A36*($B$2+1)) -> 0.0022284704 | D36: =(1-$B$3) *C36 -> 0.001539158 | E36: =B36* LN(D36) -> -25.906079 | I36: pvalue | J36: =_xlfn.CHISQ.DIST.RT(J34,J35) -> 0
A37: 30 | B37: 7 | C37: =C36*($B$1+A36)/(A37*($B$2+1)) -> 0.0019921372 | D37: =(1-$B$3) *C37 -> 0.0013759276 | E37: =B37* LN(D37) -> -46.12039
A38: 31 | B38: 5 | C38: =C37*($B$1+A37)/(A38*($B$2+1)) -> 0.0017817262 | D38: =(1-$B$3) *C38 -> 0.0012306011 | E38: =B38* LN(D38) -> -33.501263
A39: 32 | B39: 3 | C39: =C38*($B$1+A38)/(A39*($B$2+1)) -> 0.001594259 | D39: =(1-$B$3) *C39 -> 0.0011011214 | E39: =B39* LN(D39) -> -20.434278
A40: 33 | B40: 3 | C40: =C39*($B$1+A39)/(A40*($B$2+1)) -> 0.0014271217 | D40: =(1-$B$3) *C40 -> 0.00098568316 | E40: =B40* LN(D40) -> -20.766527
A41: 34 | B41: 2 | C41: =C40*($B$1+A40)/(A41*($B$2+1)) -> 0.0012780164 | D41: =(1-$B$3) *C41 -> 0.00088269925 | E41: =B41* LN(D41) -> -14.065052
A42: 35 | B42: 2 | C42: =C41*($B$1+A41)/(A42*($B$2+1)) -> 0.0011449201 | D42: =(1-$B$3) *C42 -> 0.00079077243 | E42: =B42* LN(D42) -> -14.285001
A43: 36 | B43: 3 | C43: =C42*($B$1+A42)/(A43*($B$2+1)) -> 0.0010260491 | D43: =(1-$B$3) *C43 -> 0.00070867072 | E43: =B43* LN(D43) -> -21.756359
A44: 37 | B44: 4 | C44: =C43*($B$1+A43)/(A44*($B$2+1)) -> 0.00091982868 | D44: =(1-$B$3) *C44 -> 0.00063530646 | E44: =B44* LN(D44) -> -29.445612
A45: 38 | B45: 2 | C45: =C44*($B$1+A44)/(A45*($B$2+1)) -> 0.00082486681 | D45: =(1-$B$3) *C45 -> 0.00056971829 | E45: =B45* LN(D45) -> -14.940737
A46: 39 | B46: 0 | C46: =C45*($B$1+A45)/(A46*($B$2+1)) -> 0.00073993181 | D46: =(1-$B$3) *C46 -> 0.00051105545 | E46: =B46* LN(D46) -> 0
A47: 40 | B47: 2 | C47: =C46*($B$1+A46)/(A47*($B$2+1)) -> 0.00066393254 | D47: =(1-$B$3) *C47 -> 0.00045856434 | E47: =B47* LN(D47) -> -15.37482
...

Sheet roundtrip
A1: r | B1: 0.21270839
A2: alpha | B2: 0.056499991
A3: rt | B3: 1.5643065
A4: LL | B4: =SUM(F8:F50) -> -4278.4933
A7: x | B7: N_X | C7: P(X = x) | D7: rt | E7: rescale | F7: LL | H7: x | I7: n_x | J7: P(X = x) | K7: predicted | L7: chisq
A8: 0 | B8: 975 | C8: =(B2/(B2+1))^B1 -> 0.5363805 | D8: =C8 -> 0.5363805 | E8: =D8/SUM($D$8:$D$50) -> 0.48793487 | F8: =B8* LN(E8) -> -699.63401 | H8: 0 | I8: 975 | J8: =E8 -> 0.48793487 | K8: =J8*1980 -> 966.11105 | L8: =(K8-I8)^2/I8 -> 0.081039451
A9: 1 | B9: 127 | C9: =C8*($B$1+A8)/(A9*($B$2+1)) -> 0.10799113 | D9: =IF(MOD(A9,2) = 0, C9*$B$3, C9) -> 0.10799113 | E9: =D9/SUM($D$8:$D$50) -> 0.098237427 | F9: =B9* LN(E9) -> -294.68674 | H9: 1 | I9: 127 | J9: =E9 -> 0.098237427 | K9: =J9*1980 -> 194.51011 | L9: =(K9-I9)^2/I9 -> 35.886728
A10: 2 | B10: 225 | C10: =C9*($B$1+A9)/(A10*($B$2+1)) -> 0.06197906 | D10: =IF(MOD(A10,2) = 0, C10*$B$3, C10) -> 0.096954246 | E10: =D10/SUM($D$8:$D$50) -> 0.088197386 | F10: =B10* LN(E10) -> -546.34004 | H10: 2 | I10: 225 | J10: =E10 -> 0.088197386 | K10: =J10*1980 -> 174.63082 | L10: =(K10-I10)^2/I10 -> 11.275795
A11: 3 | B11: 91 | C11: =C10*($B$1+A10)/(A11*($B$2+1)) -> 0.043269155 | D11: =IF(MOD(A11,2) = 0, C11*$B$3, C11) -> 0.043269155 | E11: =D11/SUM($D$8:$D$50) -> 0.039361107 | F11: =B11* LN(E11) -> -294.38292 | H11: 3 | I11: 91 | J11: =E11 -> 0.039361107 | K11: =J11*1980 -> 77.934991 | L11: =(K11-I11)^2/I11 -> 1.8757633
A12: 4 | B12: 97 | C12: =C11*($B$1+A11)/(A12*($B$2+1)) -> 0.032894269 | D12: =IF(MOD(A12,2) = 0, C12*$B$3, C12) -> 0.051456718 | E12: =D12/SUM($D$8:$D$50) -> 0.046809172 | F12: =B12* LN(E12) -> -296.98258 | H12: 4 | I12: 97 | J12: =E12 -> 0.046809172 | K12: =J12*1980 -> 92.682161 | L12: =(K12-I12)^2/I12 -> 0.19220341
A13: 5 | B13: 61 | C13: =C12*($B$1+A12)/(A13*($B$2+1)) -> 0.026232648 | D13: =IF(MOD(A13,2) = 0, C13*$B$3, C13) -> 0.026232648 | E13: =D13/SUM($D$8:$D$50) -> 0.023863328 | F13: =B13* LN(E13) -> -227.86016 | H13: 5 | I13: 61 | J13: =E13 -> 0.023863328 | K13: =J13*1980 -> 47.24939 | L13: =(K13-I13)^2/I13 -> 3.0996603
A14: 6 | B14: 47 | C14: =C13*($B$1+A13)/(A14*($B$2+1)) -> 0.021571722 | D14: =IF(MOD(A14,2) = 0, C14*$B$3, C14) -> 0.033744785 | E14: =D14/SUM($D$8:$D$50) -> 0.030696972 | F14: =B14* LN(E14) -> -163.72879 | H14: 6 | I14: 47 | J14: =E14 -> 0.030696972 | K14: =J14*1980 -> 60.780005 | L14: =(K14-I14)^2/I14 -> 4.0401816
A15: 7 | B15: 25 | C15: =C14*($B$1+A14)/(A15*($B$2+1)) -> 0.018121671 | D15: =IF(MOD(A15,2) = 0, C15*$B$3, C15) -> 0.018121671 | E15: =D15/SUM($D$8:$D$50) -> 0.016484931 | F15: =B15* LN(E15) -> -102.63272 | H15: 7 | I15: 25 | J15: =E15 -> 0.016484931 | K15: =J15*1980 -> 32.640163 | L15: =(K15-I15)^2/I15 -> 2.3348836
A16: 8 | B16: 38 | C16: =C15*($B$1+A15)/(A16*($B$2+1)) -> 0.015464545 | D16: =IF(MOD(A16,2) = 0, C16*$B$3, C16) -> 0.024191287 | E16: =D16/SUM($D$8:$D$50) -> 0.022006342 | F16: =B16* LN(E16) -> -145.02413 | H16: 8 | I16: 38 | J16: =E16 -> 0.022006342 | K16: =J16*1980 -> 43.572558 | L16: =(K16-I16)^2/I16 -> 0.81719466
A17: 9 | B17: 39 | C17: =C16*($B$1+A16)/(A17*($B$2+1)) -> 0.01335708 | D17: =IF(MOD(A17,2) = 0, C17*$B$3, C17) -> 0.01335708 | E17: =D17/SUM($D$8:$D$50) -> 0.012150675 | F17: =B17* LN(E17) -> -172.00445 | H17: 9 | I17: 39 | J17: =E17 -> 0.012150675 | K17: =J17*1980 -> 24.058337 | L17: =(K17-I17)^2/I17 -> 5.7244435
A18: 10 | B18: 26 | C18: =C17*($B$1+A17)/(A18*($B$2+1)) -> 0.01164741 | D18: =IF(MOD(A18,2) = 0, C18*$B$3, C18) -> 0.018220119 | E18: =D18/SUM($D$8:$D$50) -> 0.016574487 | F18: =B18* LN(E18) -> -106.59716 | H18: 10 | I18: 26 | J18: =E18 -> 0.016574487 | K18: =J18*1980 -> 32.817483 | L18: =(K18-I18)^2/I18 -> 1.7876185
A19: 11 | B19: 19 | C19: =C18*($B$1+A18)/(A19*($B$2+1)) -> 0.010235477 | D19: =IF(MOD(A19,2) = 0, C19*$B$3, C19) -> 0.010235477 | E19: =D19/SUM($D$8:$D$50) -> 0.0093110142 | F19: =B19* LN(E19) -> -88.854588 | H19: 11 | I19: 19 | J19: =E19 -> 0.0093110142 | K19: =J19*1980 -> 18.435808 | L19: =(K19-I19)^2/I19 -> 0.016753291
A20: 12 | B20: 23 | C20: =C19*($B$1+A19)/(A20*($B$2+1)) -> 0.0090524866 | D20: =IF(MOD(A20,2) = 0, C20*$B$3, C20) -> 0.014160863 | E20: =D20/SUM($D$8:$D$50) -> 0.012881861 | F20: =B20* LN(E20) -> -100.09451 | H20: 12 | I20: 23 | J20: =E20 -> 0.012881861 | K20: =J20*1980 -> 25.506085 | L20: =(K20-I20)^2/I20 -> 0.27306362
... A27: 19 | B27: 17 | C27: =C26*($B$1+A26)/(A27*($B$2+1)) -> 0.004302197 | D27: =IF(MOD(A27,2) = 0, C27*$B$3, C27) -> 0.004302197 | E27: =D27/SUM($D$8:$D$50) -> 0.0039136247 | F27: =B27* LN(E27) -> -94.235952 | H27: 19 | I27: 17 | J27: =E27 -> 0.0039136247 | K27: =J27*1980 -> 7.7489768 | L27: =(K27-I27)^2/I27 -> 5.0342018
A28: 20 | B28: 4 | C28: =C27*($B$1+A27)/(A28*($B$2+1)) -> 0.0039118247 | D28: =IF(MOD(A28,2) = 0, C28*$B$3, C28) -> 0.0061192928 | E28: =D28/SUM($D$8:$D$50) -> 0.0055666013 | F28: =B28* LN(E28) -> -20.763882 | H28: 20+ | I28: 94 | J28: =1-SUM(J8:J27) -> 0.048383945 | K28: =J28*1980 -> 95.800212 | L28: =(K28-I28)^2/I28 -> 0.034476208
A29: 21 | B29: 7 | C29: =C28*($B$1+A28)/(A29*($B$2+1)) -> 0.0035638146 | D29: =IF(MOD(A29,2) = 0, C29*$B$3, C29) -> 0.0035638146 | E29: =D29/SUM($D$8:$D$50) -> 0.0032419326 | F29: =B29* LN(E29) -> -40.121099
A30: 22 | B30: 9 | C30: =C29*($B$1+A29)/(A30*($B$2+1)) -> 0.0032525131 | D30: =IF(MOD(A30,2) = 0, C30*$B$3, C30) -> 0.0050879273 | E30: =D30/SUM($D$8:$D$50) -> 0.0046283882 | F30: =B30* LN(E30) -> -48.379919 | I30: chisq | J30: =SUM(L8:L28) -> 79.38752
A31: 23 | B31: 6 | C31: =C30*($B$1+A30)/(A31*($B$2+1)) -> 0.0029731939 | D31: =IF(MOD(A31,2) = 0, C31*$B$3, C31) -> 0.0029731939 | E31: =D31/SUM($D$8:$D$50) -> 0.0027046565 | F31: =B31* LN(E31) -> -35.476682 | I31: df | J31: =21 - 3 - 1 -> 17
A32: 24 | B32: 8 | C32: =C31*($B$1+A31)/(A32*($B$2+1)) -> 0.0027218758 | D32: =IF(MOD(A32,2) = 0, C32*$B$3, C32) -> 0.004257848 | E32: =D32/SUM($D$8:$D$50) -> 0.0038732812 | F32: =B32* LN(E32) -> -44.429226 | I32: pvalue | J32: =_xlfn.CHISQ.DIST.RT(J30,J31) -> 4.9257641e-10
A33: 25 | B33: 6 | C33: =C32*($B$1+A32)/(A33*($B$2+1)) -> 0.0024951817 | D33: =IF(MOD(A33,2) = 0, C33*$B$3, C33) -> 0.0024951817 | E33: =D33/SUM($D$8:$D$50) -> 0.0022698181 | F33: =B33* LN(E33) -> -36.528334
A34: 26 | B34: 3 | C34: =C33*($B$1+A33)/(A34*($B$2+1)) -> 0.0022902286 | D34: =IF(MOD(A34,2) = 0, C34*$B$3, C34) -> 0.0035826194 | E34: =D34/SUM($D$8:$D$50) -> 0.003259039 | F34: =B34* LN(E34) -> -17.178969 | I34: LRT vs Original
A35: 27 | B35: 9 | C35: =C34*($B$1+A34)/(A35*($B$2+1)) -> 0.0021045413 | D35: =IF(MOD(A35,2) = 0, C35*$B$3, C35) -> 0.0021045413 | E35: =D35/SUM($D$8:$D$50) -> 0.0019144602 | F35: =B35* LN(E35) -> -56.324876 | I35: chisq | J35: =2 * (B4 - 'NBD fit (bad)'!B3) -> 4546.2677
A36: 28 | B36: 5 | C36: =C35*($B$1+A35)/(A36*($B$2+1)) -> 0.0019359837 | D36: =IF(MOD(A36,2) = 0, C36*$B$3, C36) -> 0.0030284719 | E36: =D36/SUM($D$8:$D$50) -> 0.0027549418 | F36: =B36* LN(E36) -> -29.471795 | I36: df | J36: =3 - 2 -> 1
A37: 29 | B37: 4 | C37: =C36*($B$1+A36)/(A37*($B$2+1)) -> 0.001782703 | D37: =IF(MOD(A37,2) = 0, C37*$B$3, C37) -> 0.001782703 | E37: =D37/SUM($D$8:$D$50) -> 0.0016216901 | F37: =B37* LN(E37) -> -25.697146 | I37: pvalue | J37: =_xlfn.CHISQ.DIST.RT(J35,J36) -> 0
A38: 30 | B38: 7 | C38: =C37*($B$1+A37)/(A38*($B$2+1)) -> 0.0016430851 | D38: =IF(MOD(A38,2) = 0, C38*$B$3, C38) -> 0.0025702887 | E38: =D38/SUM($D$8:$D$50) -> 0.0023381415 | F38: =B38* LN(E38) -> -42.408792
A39: 31 | B39: 5 | C39: =C38*($B$1+A38)/(A39*($B$2+1)) -> 0.0015157184 | D39: =IF(MOD(A39,2) = 0, C39*$B$3, C39) -> 0.0015157184 | E39: =D39/SUM($D$8:$D$50) -> 0.0013788195 | F39: =B39* LN(E39) -> -32.932638 | I39: LRT vs Spike
A40: 32 | B40: 3 | C40: =C39*($B$1+A39)/(A40*($B$2+1)) -> 0.0013993634 | D40: =IF(MOD(A40,2) = 0, C40*$B$3, C40) -> 0.0021890332 | E40: =D40/SUM($D$8:$D$50) -> 0.0019913208 | F40: =B40* LN(E40) -> -18.656871 | I40: chisq | J40: =2 *(B4-zerospike!B4) -> 48.268082
A41: 33 | B41: 3 | C41: =C40*($B$1+A40)/(A41*($B$2+1)) -> 0.0012929279 | D41: =IF(MOD(A41,2) = 0, C41*$B$3, C41) -> 0.0012929279 | E41: =D41/SUM($D$8:$D$50) -> 0.0011761513 | F41: =B41* LN(E41) -> -20.236523 | I41: df | J41: =3 - 2 -> 1
A42: 34 | B42: 2 | C42: =C41*($B$1+A41)/(A42*($B$2+1)) -> 0.0011954466 | D42: =IF(MOD(A42,2) = 0, C42*$B$3, C42) -> 0.0018700449 | E42: =D42/SUM($D$8:$D$50) -> 0.0017011433 | F42: =B42* LN(E42) -> -12.752909 | I42: pvalue | J42: =_xlfn.CHISQ.DIST.RT(J40,J41) -> 3.7175425e-12
A43: 35 | B43: 2 | C43: =C42*($B$1+A42)/(A43*($B$2+1)) -> 0.0011060636 | D43: =IF(MOD(A43,2) = 0, C43*$B$3, C43) -> 0.0011060636 | E43: =D43/SUM($D$8:$D$50) -> 0.0010061645 | F43: =B43* LN(E43) -> -13.803219
A44: 36 | B44: 3 | C44: =C43*($B$1+A43)/(A44*($B$2+1)) -> 0.0010240179 | D44: =IF(MOD(A44,2) = 0, C44*$B$3, C44) -> 0.0016018778 | E44: =D44/SUM($D$8:$D$50) -> 0.001457197 | F44: =B44* LN(E44) -> -19.593722
A45: 37 | B45: 4 | C45: =C44*($B$1+A44)/(A45*($B$2+1)) -> 0.000948631 | D45: =IF(MOD(A45,2) = 0, C45*$B$3, C45) -> 0.000948631 | E45: =D45/SUM($D$8:$D$50) -> 0.00086295112 | F45: =B45* LN(E45) -> -28.22061
A46: 38 | B46: 2 | C46: =C45*($B$1+A45)/(A46*($B$2+1)) -> 0.00087929682 | D46: =IF(MOD(A46,2) = 0, C46*$B$3, C46) -> 0.0013754897 | E46: =D46/SUM($D$8:$D$50) -> 0.0012512562 | F46: =B46* LN(E46) -> -13.367215
A47: 39 | B47: 0 | C47: =C46*($B$1+A46)/(A47*($B$2+1)) -> 0.0008154723 | D47: =IF(MOD(A47,2) = 0, C47*$B$3, C47) -> 0.0008154723 | E47: =D47/SUM($D$8:$D$50) -> 0.00074181925 | F47: =B47* LN(E47) -> 0
A48: 40 | B48: 2 | C48: =C47*($B$1+A47)/(A48*($B$2+1)) -> 0.00075667009 | D48: =IF(MOD(A48,2) = 0, C48*$B$3, C48) -> 0.0011836639 | E48: =D48/SUM($D$8:$D$50) -> 0.001076756 | F48: =B48* LN(E48) -> -13.667605
...

Sheet roundtrip+zerospike
A1: r | B1: 0.37661663
A2: alpha | B2: 0.076142292
A3: rt | B3: 1.511842
A4: spike@0 | B4: 0.2468593
A5: LL | B5: =SUM(G8:G50) -> -4274.6944
A7: x | B7: N_X | C7: P(X = x) | D7: rt | E7: rescale | F7: spike | G7: LL | I7: x | J7: n_x | K7: P(X = x) | L7: predicted | M7: chisq
A8: 0 | B8: 975 | C8: =(B2/(B2+1))^B1 -> 0.36880693 | D8: =C8 -> 0.36880693 | E8: =D8/SUM($D$8:$D$50) -> 0.32605366 | F8: =$B$4+(1-$B$4)*E8 -> 0.49242358 | G8: =B8*LN(F8) -> -690.70559 | I8: 0 | J8: 975 | K8: =F8 -> 0.49242358 | L8: =K8*1980 -> 974.9987 | M8: =(L8-J8)^2/J8 -> 1.7412283e-09
A9: 1 | B9: 127 | C9: =C8*($B$1+A8)/(A9*($B$2+1)) -> 0.12907106 | D9: =IF(MOD(A9,2) = 0, C9*$B$3, C9) -> 0.12907106 | E9: =D9/SUM($D$8:$D$50) -> 0.11410873 | F9: =(1-$B$4) *E9 -> 0.085939928 | G9: =B9*LN(F9) -> -311.67156 | I9: 1 | J9: 127 | K9: =F9 -> 0.085939928 | L9: =K9*1980 -> 170.16106 | M9: =(L9-J9)^2/J9 -> 14.668322
A10: 2 | B10: 225 | C10: =C9*($B$1+A9)/(A10*($B$2+1)) -> 0.082554772 | D10: =IF(MOD(A10,2) = 0, C10*$B$3, C10) -> 0.12480977 | E10: =D10/SUM($D$8:$D$50) -> 0.11034143 | F10: =(1-$B$4) *E10 -> 0.08310262 | G10: =B10*LN(F10) -> -559.72779 | I10: 2 | J10: 225 | K10: =F10 -> 0.08310262 | L10: =K10*1980 -> 164.54319 | M10: =(L10-J10)^2/J10 -> 16.244561
A11: 3 | B11: 91 | C11: =C10*($B$1+A10)/(A11*($B$2+1)) -> 0.060772956 | D11: =IF(MOD(A11,2) = 0, C11*$B$3, C11) -> 0.060772956 | E11: =D11/SUM($D$8:$D$50) -> 0.053727961 | F11: =(1-$B$4) *E11 -> 0.040464714 | G11: =B11*LN(F11) -> -291.86657 | I11: 3 | J11: 91 | K11: =F11 -> 0.040464714 | L11: =K11*1980 -> 80.120134 | M11: =(L11-J11)^2/J11 -> 1.3007855
A12: 4 | B12: 97 | C12: =C11*($B$1+A11)/(A12*($B$2+1)) -> 0.047671896 | D12: =IF(MOD(A12,2) = 0, C12*$B$3, C12) -> 0.072072376 | E12: =D12/SUM($D$8:$D$50) -> 0.063717516 | F12: =(1-$B$4) *E12 -> 0.047988255 | G12: =B12*LN(F12) -> -294.5695 | I12: 4 | J12: 97 | K12: =F12 -> 0.047988255 | L12: =K12*1980 -> 95.016744 | M12: =(L12-J12)^2/J12 -> 0.040549518
A13: 5 | B13: 61 | C13: =C12*($B$1+A12)/(A13*($B$2+1)) -> 0.038775841 | D13: =IF(MOD(A13,2) = 0, C13*$B$3, C13) -> 0.038775841 | E13: =D13/SUM($D$8:$D$50) -> 0.034280822 | F13: =(1-$B$4) *E13 -> 0.025818282 | G13: =B13*LN(F13) -> -223.05702 | I13: 5 | J13: 61 | K13: =F13 -> 0.025818282 | L13: =K13*1980 -> 51.120199 | M13: =(L13-J13)^2/J13 -> 1.6001717
A14: 6 | B14: 47 | C14: =C13*($B$1+A13)/(A14*($B$2+1)) -> 0.03228861 | D14: =IF(MOD(A14,2) = 0, C14*$B$3, C14) -> 0.048815277 | E14: =D14/SUM($D$8:$D$50) -> 0.043156455 | F14: =(1-$B$4) *E14 -> 0.032502883 | G14: =B14*LN(F14) -> -161.04205 | I14: 6 | J14: 47 | K14: =F14 -> 0.032502883 | L14: =K14*1980 -> 64.355707 | M14: =(L14-J14)^2/J14 -> 6.4089485
A15: 7 | B15: 25 | C15: =C14*($B$1+A14)/(A15*($B$2+1)) -> 0.027332032 | D15: =IF(MOD(A15,2) = 0, C15*$B$3, C15) -> 0.027332032 | E15: =D15/SUM($D$8:$D$50) -> 0.024163616 | F15: =(1-$B$4) *E15 -> 0.018198602 | G15: =B15*LN(F15) -> -100.16026 | I15: 7 | J15: 25 | K15: =F15 -> 0.018198602 | L15: =K15*1980 -> 36.033232 | M15: =(L15-J15)^2/J15 -> 4.8692887
A16: 8 | B16: 38 | C16: =C15*($B$1+A15)/(A16*($B$2+1)) -> 0.023419059 | D16: =IF(MOD(A16,2) = 0, C16*$B$3, C16) -> 0.035405918 | E16: =D16/SUM($D$8:$D$50) -> 0.031301551 | F16: =(1-$B$4) *E16 -> 0.023574472 | G16: =B16*LN(F16) -> -142.40845 | I16: 8 | J16: 38 | K16: =F16 -> 0.023574472 | L16: =K16*1980 -> 46.677454 | M16: =(L16-J16)^2/J16 -> 1.981532
A17: 9 | B17: 39 | C17: =C16*($B$1+A16)/(A17*($B$2+1)) -> 0.020254703 | D17: =IF(MOD(A17,2) = 0, C17*$B$3, C17) -> 0.020254703 | E17: =D17/SUM($D$8:$D$50) -> 0.017906713 | F17: =(1-$B$4) *E17 -> 0.013486274 | G17: =B17*LN(F17) -> -167.93723 | I17: 9 | J17: 39 | K17: =F17 -> 0.013486274 | L17: =K17*1980 -> 26.702823 | M17: =(L17-J17)^2/J17 -> 3.8774502
A18: 10 | B18: 26 | C18: =C17*($B$1+A17)/(A18*($B$2+1)) -> 0.017648278 | D18: =IF(MOD(A18,2) = 0, C18*$B$3, C18) -> 0.026681408 | E18: =D18/SUM($D$8:$D$50) -> 0.023588414 | F18: =(1-$B$4) *E18 -> 0.017765395 | G18: =B18*LN(F18) -> -104.79307 | I18: 10 | J18: 26 | K18: =F18 -> 0.017765395 | L18: =K18*1980 -> 35.175482 | M18: =(L18-J18)^2/J18 -> 3.2380564
A19: 11 | B19: 19 | C19: =C18*($B$1+A18)/(A19*($B$2+1)) -> 0.015470193 | D19: =IF(MOD(A19,2) = 0, C19*$B$3, C19) -> 0.015470193 | E19: =D19/SUM($D$8:$D$50) -> 0.013676839 | F19: =(1-$B$4) *E19 -> 0.010300584 | G19: =B19*LN(F19) -> -86.935539 | I19: 11 | J19: 19 | K19: =F19 -> 0.010300584 | L19: =K19*1980 -> 20.395156 | M19: =(L19-J19)^2/J19 -> 0.10244525
A20: 12 | B20: 23 | C20: =C19*($B$1+A19)/(A20*($B$2+1)) -> 0.013628809 | D20: =IF(MOD(A20,2) = 0, C20*$B$3, C20) -> 0.020604606 | E20: =D20/SUM($D$8:$D$50) -> 0.018216054 | F20: =(1-$B$4) *E20 -> 0.013719252 | G20: =B20*LN(F20) -> -98.645969 | I20: 12 | J20: 23 | K20: =F20 -> 0.013719252 | L20: =K20*1980 -> 27.164119 | M20: =(L20-J20)^2/J20 -> 0.75390804
... A27: 19 | B27: 17 | C27: =C26*($B$1+A26)/(A27*($B$2+1)) -> 0.0061451573 | D27: =IF(MOD(A27,2) = 0, C27*$B$3, C27) -> 0.0061451573 | E27: =D27/SUM($D$8:$D$50) -> 0.0054327911 | F27: =(1-$B$4) *E27 -> 0.004091656 | G27: =B27*LN(F27) -> -93.479693 | I27: 19 | J27: 17 | K27: =F27 -> 0.004091656 | L27: =K27*1980 -> 8.101479 | M27: =(L27-J27)^2/J27 -> 4.6578633
A28: 20 | B28: 4 | C28: =C27*($B$1+A27)/(A28*($B$2+1)) -> 0.0055323704 | D28: =IF(MOD(A28,2) = 0, C28*$B$3, C28) -> 0.0083640702 | E28: =D28/SUM($D$8:$D$50) -> 0.0073944805 | F28: =(1-$B$4) *E28 -> 0.0055690842 | G28: =B28*LN(F28) -> -20.762099 | I28: 20+ | J28: 94 | K28: =1-SUM(K8:K27) -> 0.044942038 | L28: =K28*1980 -> 88.985235 | M28: =(L28-J28)^2/J28 -> 0.26753051
A29: 21 | B29: 7 | C29: =C28*($B$1+A28)/(A29*($B$2+1)) -> 0.0049883203 | D29: =IF(MOD(A29,2) = 0, C29*$B$3, C29) -> 0.0049883203 | E29: =D29/SUM($D$8:$D$50) -> 0.0044100583 | F29: =(1-$B$4) *E29 -> 0.0033213944 | G29: =B29*LN(F29) -> -39.951594
A30: 22 | B30: 9 | C30: =C29*($B$1+A29)/(A30*($B$2+1)) -> 0.0045040263 | D30: =IF(MOD(A30,2) = 0, C30*$B$3, C30) -> 0.0068093763 | E30: =D30/SUM($D$8:$D$50) -> 0.0060200117 | F30: =(1-$B$4) *E30 -> 0.0045339158 | G30: =B30*LN(F30) -> -48.565524 | K30: chisq | L30: =SUM(M8:M28) -> 68.37462
A31: 23 | B31: 6 | C31: =C30*($B$1+A30)/(A31*($B$2+1)) -> 0.0040719066 | D31: =IF(MOD(A31,2) = 0, C31*$B$3, C31) -> 0.0040719066 | E31: =D31/SUM($D$8:$D$50) -> 0.0035998782 | F31: =(1-$B$4) *E31 -> 0.0027112148 | G31: =B31*LN(F31) -> -35.462151 | K31: df | L31: =21 - 4 - 1 -> 16
A32: 24 | B32: 8 | C32: =C31*($B$1+A31)/(A32*($B$2+1)) -> 0.0036855179 | D32: =IF(MOD(A32,2) = 0, C32*$B$3, C32) -> 0.0055719208 | E32: =D32/SUM($D$8:$D$50) -> 0.004926006 | F32: =(1-$B$4) *E32 -> 0.0037099756 | G32: =B32*LN(F32) -> -44.77384 | K32: pvalue | L32: =_xlfn.CHISQ.DIST.RT(L30,L31) -> 1.9186555e-08
A33: 25 | B33: 6 | C33: =C32*($B$1+A32)/(A33*($B$2+1)) -> 0.0033393523 | D33: =IF(MOD(A33,2) = 0, C33*$B$3, C33) -> 0.0033393523 | E33: =D33/SUM($D$8:$D$50) -> 0.002952244 | F33: =(1-$B$4) *E33 -> 0.0022234551 | G33: =B33*LN(F33) -> -36.652158
A34: 26 | B34: 3 | C34: =C33*($B$1+A33)/(A34*($B$2+1)) -> 0.0030286767 | D34: =IF(MOD(A34,2) = 0, C34*$B$3, C34) -> 0.0045788807 | E34: =D34/SUM($D$8:$D$50) -> 0.0040480823 | F34: =(1-$B$4) *E34 -> 0.0030487755 | G34: =B34*LN(F34) -> -17.379046 | K34: LRT vs Original
A35: 27 | B35: 9 | C35: =C34*($B$1+A34)/(A35*($B$2+1)) -> 0.0027494038 | D35: =IF(MOD(A35,2) = 0, C35*$B$3, C35) -> 0.0027494038 | E35: =D35/SUM($D$8:$D$50) -> 0.0024306842 | F35: =(1-$B$4) *E35 -> 0.0018306472 | G35: =B35*LN(F35) -> -56.727771 | K35: chisq | L35: =2 * (B5 - 'NBD fit (bad)'!B3) -> 4553.8655
A36: 28 | B36: 5 | C36: =C35*($B$1+A35)/(A36*($B$2+1)) -> 0.0024979893 | D36: =IF(MOD(A36,2) = 0, C36*$B$3, C36) -> 0.0037765653 | E36: =D36/SUM($D$8:$D$50) -> 0.0033387738 | F36: =(1-$B$4) *E36 -> 0.0025145664 | G36: =B36*LN(F36) -> -29.928274 | K36: df | L36: =4 - 2 -> 2
A37: 29 | B37: 4 | C37: =C36*($B$1+A36)/(A37*($B$2+1)) -> 0.002271347 | D37: =IF(MOD(A37,2) = 0, C37*$B$3, C37) -> 0.002271347 | E37: =D37/SUM($D$8:$D$50) -> 0.0020080453 | F37: =(1-$B$4) *E37 -> 0.0015123406 | G37: =B37*LN(F37) -> -25.976387 | K37: pvalue | L37: =_xlfn.CHISQ.DIST.RT(L35,L36) -> 0
A38: 30 | B38: 7 | C38: =C37*($B$1+A37)/(A38*($B$2+1)) -> 0.0020667803 | D38: =IF(MOD(A38,2) = 0, C38*$B$3, C38) -> 0.0031246453 | E38: =D38/SUM($D$8:$D$50) -> 0.0027624265 | F38: =(1-$B$4) *E38 -> 0.0020804958 | G38: =B38*LN(F38) -> -43.226043
A39: 31 | B39: 5 | C39: =C38*($B$1+A38)/(A39*($B$2+1)) -> 0.0018819251 | D39: =IF(MOD(A39,2) = 0, C39*$B$3, C39) -> 0.0018819251 | E39: =D39/SUM($D$8:$D$50) -> 0.0016637663 | F39: =(1-$B$4) *E39 -> 0.0012530501 | G39: =B39*LN(F39) -> -33.410873
A40: 32 | B40: 3 | C40: =C39*($B$1+A39)/(A40*($B$2+1)) -> 0.0017147024 | D40: =IF(MOD(A40,2) = 0, C40*$B$3, C40) -> 0.0025923592 | E40: =D40/SUM($D$8:$D$50) -> 0.0022918446 | F40: =(1-$B$4) *E40 -> 0.0017260815 | G40: =B40*LN(F40) -> -19.085704
A41: 33 | B41: 3 | C41: =C40*($B$1+A40)/(A41*($B$2+1)) -> 0.0015632793 | D41: =IF(MOD(A41,2) = 0, C41*$B$3, C41) -> 0.0015632793 | E41: =D41/SUM($D$8:$D$50) -> 0.001382059 | F41: =(1-$B$4) *E41 -> 0.0010408849 | G41: =B41*LN(F41) -> -20.603052
A42: 34 | B42: 2 | C42: =C41*($B$1+A41)/(A42*($B$2+1)) -> 0.0014260353 | D42: =IF(MOD(A42,2) = 0, C42*$B$3, C42) -> 0.0021559401 | E42: =D42/SUM($D$8:$D$50) -> 0.0019060167 | F42: =(1-$B$4) *E42 -> 0.0014354987 | G42: =B42*LN(F42) -> -13.092486
A43: 35 | B43: 2 | C43: =C42*($B$1+A42)/(A43*($B$2+1)) -> 0.0013015344 | D43: =IF(MOD(A43,2) = 0, C43*$B$3, C43) -> 0.0013015344 | E43: =D43/SUM($D$8:$D$50) -> 0.0011506564 | F43: =(1-$B$4) *E43 -> 0.00086660618 | G43: =B43*LN(F43) -> -14.101852
A44: 36 | B44: 3 | C44: =C43*($B$1+A43)/(A44*($B$2+1)) -> 0.0011885016 | D44: =IF(MOD(A44,2) = 0, C44*$B$3, C44) -> 0.0017968266 | E44: =D44/SUM($D$8:$D$50) -> 0.0015885328 | F44: =(1-$B$4) *E44 -> 0.0011963887 | G44: =B44*LN(F44) -> -20.185343
A45: 37 | B45: 4 | C45: =C44*($B$1+A44)/(A45*($B$2+1)) -> 0.001085802 | D45: =IF(MOD(A45,2) = 0, C45*$B$3, C45) -> 0.001085802 | E45: =D45/SUM($D$8:$D$50) -> 0.00095993238 | F45: =(1-$B$4) *E45 -> 0.00072296414 | G45: =B45*LN(F45) -> -28.928604
A46: 38 | B46: 2 | C46: =C45*($B$1+A45)/(A46*($B$2+1)) -> 0.00099242416 | D46: =IF(MOD(A46,2) = 0, C46*$B$3, C46) -> 0.0015003886 | E46: =D46/SUM($D$8:$D$50) -> 0.0013264587 | F46: =(1-$B$4) *E46 -> 0.00099901006 | G46: =B46*LN(F46) -> -13.817491
A47: 39 | B47: 0 | C47: =C46*($B$1+A46)/(A47*($B$2+1)) -> 0.00090746463 | D47: =IF(MOD(A47,2) = 0, C47*$B$3, C47) -> 0.00090746463 | E47: =D47/SUM($D$8:$D$50) -> 0.00080226844 | F47: =(1-$B$4) *E47 -> 0.00060422101 | G47: =B47*LN(F47) -> 0
...

Sheet roundtrip+zerospike+seg
A1: r1 | B1: 0.32140265
A2: alpha1 | B2: 0.075841563
A3: r2 | B3: 0.034004033
A4: alpha2 | B4: 2.4897837e-06
A5: frequent | B5: 0.37076465
A6: rt | B6: 2.1777235
A7: spike@0 | B7: 1e-06
A8: LL | B8: =SUM(I16:I58) -> -4279.0017
A15: x | B15: N_X | C15: P(X = x | r1, a1) | D15: P(X = x | r2, a2) | E15: P(X = x) | F15: rt | G15: rescale | H15: spike | I15: LL | K15: x | L15: n_x | M15: P(X = x) | N15: predicted | O15: chisq
A16: 0 | B16: 975 | C16: =(B2/(B2+1))^B1 -> 0.42637843 | D16: =(B4/(B4+1))^B3 -> 0.64483241 | E16: =C16*(1 - $B$5) + D16*$B$5 -> 0.50737345 | F16: =E16 -> 0.50737345 | G16: =E16/SUM($E$16:$E$58) -> 0.49230771 | H16: =$B$7+(1-$B$7)*G16 -> 0.49230822 | I16: =B16*LN(H16) -> -690.93404 | K16: 0 | L16: 975 | M16: =H16 -> 0.49230822 | N16: =M16*1980 -> 974.77027 | O16: =(N16-L16)^2/L16 -> 5.4127553e-05
A17: 1 | B17: 127 | C17: =C16*($B$1+A16)/(A17*($B$2+1)) -> 0.12737857 | D17: =C16*($B$3+A16)/(A17*($B$4+1)) -> 0.01449855 | E17: =C17*(1 - $B$5) + D17*$B$5 -> 0.08552665 | F17: =IF(MOD(A17,2) = 0, E17*B$6, E17) -> 0.08552665 | G17: =E17/SUM($E$16:$E$58) -> 0.082987057 | H17: =(1-$B$7) *G17 -> 0.082986974 | I17: =B17*LN(H17) -> -316.1121 | K17: 1 | L17: 127 | M17: =H17 -> 0.082986974 | N17: =M17*1980 -> 164.31421 | O17: =(N17-L17)^2/L17 -> 10.963387
A18: 2 | B18: 225 | C18: =C17*($B$1+A17)/(A18*($B$2+1)) -> 0.07822638 | D18: =C17*($B$3+A17)/(A18*($B$4+1)) -> 0.065854814 | E18: =C18*(1 - $B$5) + D18*$B$5 -> 0.073639441 | F18: =IF(MOD(A18,2) = 0, E18*B$6, E18) -> 0.16036634 | G18: =E18/SUM($E$16:$E$58) -> 0.071452822 | H18: =(1-$B$7) *G18 -> 0.07145275 | I18: =B18*LN(H18) -> -593.71175 | K18: 2 | L18: 225 | M18: =H18 -> 0.07145275 | N18: =M18*1980 -> 141.47645 | O18: =(N18-L18)^2/L18 -> 31.005263
A19: 3 | B19: 91 | C19: =C18*($B$1+A18)/(A19*($B$2+1)) -> 0.056264458 | D19: =C18*($B$3+A18)/(A19*($B$4+1)) -> 0.053037459 | E19: =C19*(1 - $B$5) + D19*$B$5 -> 0.055068001 | F19: =IF(MOD(A19,2) = 0, E19*B$6, E19) -> 0.055068001 | G19: =E19/SUM($E$16:$E$58) -> 0.053432834 | H19: =(1-$B$7) *G19 -> 0.053432781 | I19: =B19*LN(H19) -> -266.56911 | K19: 3 | L19: 91 | M19: =H19 -> 0.053432781 | N19: =M19*1980 -> 105.79691 | O19: =(N19-L19)^2/L19 -> 2.4060267
A20: 4 | B20: 97 | C20: =C19*($B$1+A19)/(A20*($B$2+1)) -> 0.043425753 | D20: =C19*($B$3+A19)/(A20*($B$4+1)) -> 0.042676542 | E20: =C20*(1 - $B$5) + D20*$B$5 -> 0.043147972 | F20: =IF(MOD(A20,2) = 0, E20*B$6, E20) -> 0.093964351 | G20: =E20/SUM($E$16:$E$58) -> 0.041866754 | H20: =(1-$B$7) *G20 -> 0.041866712 | I20: =B20*LN(H20) -> -307.80663 | K20: 4 | L20: 97 | M20: =H20 -> 0.041866712 | N20: =M20*1980 -> 82.89609 | O20: =(N20-L20)^2/L20 -> 2.0507245
A21: 5 | B21: 61 | C21: =C20*($B$1+A20)/(A21*($B$2+1)) -> 0.034886208 | D21: =C20*($B$3+A20)/(A21*($B$4+1)) -> 0.035035845 | E21: =C21*(1 - $B$5) + D21*$B$5 -> 0.034941688 | F21: =IF(MOD(A21,2) = 0, E21*B$6, E21) -> 0.034941688 | G21: =E21/SUM($E$16:$E$58) -> 0.033904144 | H21: =(1-$B$7) *G21 -> 0.03390411 | I21: =B21*LN(H21) -> -206.43736 | K21: 5 | L21: 61 | M21: =H21 -> 0.03390411 | N21: =M21*1980 -> 67.130139 | O21: =(N21-L21)^2/L21 -> 0.61604263
A22: 6 | B22: 47 | C22: =C21*($B$1+A21)/(A22*($B$2+1)) -> 0.028759433 | D22: =C21*($B$3+A21)/(A22*($B$4+1)) -> 0.029269479 | E22: =C22*(1 - $B$5) + D22*$B$5 -> 0.02894854 | F22: =IF(MOD(A22,2) = 0, E22*B$6, E22) -> 0.063041915 | G22: =E22/SUM($E$16:$E$58) -> 0.028088954 | H22: =(1-$B$7) *G22 -> 0.028088926 | I22: =B22*LN(H22) -> -167.90185 | K22: 6 | L22: 47 | M22: =H22 -> 0.028088926 | N22: =M22*1980 -> 55.616074 | O22: =(N22-L22)^2/L22 -> 1.5795049
A23: 7 | B23: 25 | C23: =C22*($B$1+A22)/(A23*($B$2+1)) -> 0.024140564 | D23: =C22*($B$3+A22)/(A23*($B$4+1)) -> 0.024790586 | E23: =C23*(1 - $B$5) + D23*$B$5 -> 0.024381569 | F23: =IF(MOD(A23,2) = 0, E23*B$6, E23) -> 0.024381569 | G23: =E23/SUM($E$16:$E$58) -> 0.023657593 | H23: =(1-$B$7) *G23 -> 0.02365757 | I23: =B23*LN(H23) -> -93.601804 | K23: 7 | L23: 25 | M23: =H23 -> 0.02365757 | N23: =M23*1980 -> 46.841988 | O23: =(N23-L23)^2/L23 -> 19.082897
A24: 8 | B24: 38 | C24: =C23*($B$1+A23)/(A24*($B$2+1)) -> 0.020535411 | D24: =C23*($B$3+A23)/(A24*($B$4+1)) -> 0.02122555 | E24: =C24*(1 - $B$5) + D24*$B$5 -> 0.02079129 | F24: =IF(MOD(A24,2) = 0, E24*B$6, E24) -> 0.045277681 | G24: =E24/SUM($E$16:$E$58) -> 0.020173923 | H24: =(1-$B$7) *G24 -> 0.020173902 | I24: =B24*LN(H24) -> -148.32789 | K24: 8 | L24: 38 | M24: =H24 -> 0.020173902 | N24: =M24*1980 -> 39.944327 | O24: =(N24-L24)^2/L24 -> 0.099484376
A25: 9 | B25: 39 | C25: =C24*($B$1+A24)/(A25*($B$2+1)) -> 0.017648553 | D25: =C24*($B$3+A24)/(A25*($B$4+1)) -> 0.018331241 | E25: =C25*(1 - $B$5) + D25*$B$5 -> 0.01790167 | F25: =IF(MOD(A25,2) = 0, E25*B$6, E25) -> 0.01790167 | G25: =E25/SUM($E$16:$E$58) -> 0.017370105 | H25: =(1-$B$7) *G25 -> 0.017370088 | I25: =B25*LN(H25) -> -158.06722 | K25: 9 | L25: 39 | M25: =H25 -> 0.017370088 | N25: =M25*1980 -> 34.392773 | O25: =(N25-L25)^2/L25 -> 0.54427016
A26: 10 | B26: 26 | C26: =C25*($B$1+A25)/(A26*($B$2+1)) -> 0.015291217 | D26: =C25*($B$3+A25)/(A26*($B$4+1)) -> 0.015943671 | E26: =C26*(1 - $B$5) + D26*$B$5 -> 0.015533124 | F26: =IF(MOD(A26,2) = 0, E26*B$6, E26) -> 0.033826849 | G26: =E26/SUM($E$16:$E$58) -> 0.01507189 | H26: =(1-$B$7) *G26 -> 0.015071875 | I26: =B26*LN(H26) -> -109.06805 | K26: 10 | L26: 26 | M26: =H26 -> 0.015071875 | N26: =M26*1980 -> 29.842312 | O26: =(N26-L26)^2/L26 -> 0.56782163
A27: 11 | B27: 19 | C27: =C26*($B$1+A26)/(A27*($B$2+1)) -> 0.013336436 | D27: =C26*($B$3+A26)/(A27*($B$4+1)) -> 0.013948341 | E27: =C27*(1 - $B$5) + D27*$B$5 -> 0.013563309 | F27: =IF(MOD(A27,2) = 0, E27*B$6, E27) -> 0.013563309 | G27: =E27/SUM($E$16:$E$58) -> 0.013160566 | H27: =(1-$B$7) *G27 -> 0.013160552 | I27: =B27*LN(H27) -> -82.280096 | K27: 11 | L27: 19 | M27: =H27 -> 0.013160552 | N27: =M27*1980 -> 26.057894 | O27: =(N27-L27)^2/L27 -> 2.6217823
A28: 12 | B28: 23 | C28: =C27*($B$1+A27)/(A28*($B$2+1)) -> 0.011695275 | D28: =C27*($B$3+A27)/(A28*($B$4+1)) -> 0.012262827 | E28: =C28*(1 - $B$5) + D28*$B$5 -> 0.011905703 | F28: =IF(MOD(A28,2) = 0, E28*B$6, E28) -> 0.02592733 | G28: =E28/SUM($E$16:$E$58) -> 0.01155218 | H28: =(1-$B$7) *G28 -> 0.011552169 | I28: =B28*LN(H28) -> -102.60029 | K28: 12 | L28: 23 | M28: =H28 -> 0.011552169 | N28: =M28*1980 -> 22.873294 | O28: =(N28-L28)^2/L28 -> 0.00069801485
... A35: 19 | B35: 17 | C35: =C34*($B$1+A34)/(A35*($B$2+1)) -> 0.0051500093 | D35: =C34*($B$3+A34)/(A35*($B$4+1)) -> 0.0054536679 | E35: =C35*(1 - $B$5) + D35*$B$5 -> 0.0052625952 | F35: =IF(MOD(A35,2) = 0, E35*B$6, E35) -> 0.0052625952 | G35: =E35/SUM($E$16:$E$58) -> 0.0051063299 | H35: =(1-$B$7) *G35 -> 0.0051063247 | I35: =B35*LN(H35) -> -89.713681 | K35: 19 | L35: 17 | M35: =H35 -> 0.0051063247 | N35: =M35*1980 -> 10.110523 | O35: =(N35-L35)^2/L35 -> 2.7920525
A36: 20 | B36: 4 | C36: =C35*($B$1+A35)/(A36*($B$2+1)) -> 0.0046245379 | D36: =C35*($B$3+A35)/(A36*($B$4+1)) -> 0.0049012526 | E36: =C36*(1 - $B$5) + D36*$B$5 -> 0.004727134 | F36: =IF(MOD(A36,2) = 0, E36*B$6, E36) -> 0.010294391 | G36: =E36/SUM($E$16:$E$58) -> 0.0045867684 | H36: =(1-$B$7) *G36 -> 0.0045867638 | I36: =B36*LN(H36) -> -21.538322 | K36: 20+ | L36: 94 | M36: =1-SUM(M16:M35) -> 0.043473693 | N36: =M36*1980 -> 86.077911 | O36: =(N36-L36)^2/L36 -> 0.66765415
A37: 21 | B37: 7 | C37: =C36*($B$1+A36)/(A37*($B$2+1)) -> 0.0041596273 | D37: =C36*($B$3+A36)/(A37*($B$4+1)) -> 0.0044117991 | E37: =C37*(1 - $B$5) + D37*$B$5 -> 0.0042531237 | F37: =IF(MOD(A37,2) = 0, E37*B$6, E37) -> 0.0042531237 | G37: =E37/SUM($E$16:$E$58) -> 0.0041268332 | H37: =(1-$B$7) *G37 -> 0.0041268291 | I37: =B37*LN(H37) -> -38.431722
A38: 22 | B38: 9 | C38: =C37*($B$1+A37)/(A38*($B$2+1)) -> 0.0037471337 | D38: =C37*($B$3+A37)/(A38*($B$4+1)) -> 0.0039769727 | E38: =C38*(1 - $B$5) + D38*$B$5 -> 0.0038323499 | F38: =IF(MOD(A38,2) = 0, E38*B$6, E38) -> 0.0083457982 | G38: =E38/SUM($E$16:$E$58) -> 0.0037185537 | H38: =(1-$B$7) *G38 -> 0.0037185499 | I38: =B38*LN(H38) -> -50.349793 | M38: chisq | N38: =SUM(O16:O36) -> 80.395875
A39: 23 | B39: 6 | C39: =C38*($B$1+A38)/(A39*($B$2+1)) -> 0.0033802165 | D39: =C38*($B$3+A38)/(A39*($B$4+1)) -> 0.0035897458 | E39: =C39*(1 - $B$5) + D39*$B$5 -> 0.0034579025 | F39: =IF(MOD(A39,2) = 0, E39*B$6, E39) -> 0.0034579025 | G39: =E39/SUM($E$16:$E$58) -> 0.003355225 | H39: =(1-$B$7) *G39 -> 0.0033552217 | I39: =B39*LN(H39) -> -34.183425 | M39: df | N39: =21 - 7 - 1 -> 13
A40: 24 | B40: 8 | C40: =C39*($B$1+A39)/(A40*($B$2+1)) -> 0.0030530901 | D40: =C39*($B$3+A39)/(A40*($B$4+1)) -> 0.0032441553 | E40: =C40*(1 - $B$5) + D40*$B$5 -> 0.0031239303 | F40: =IF(MOD(A40,2) = 0, E40*B$6, E40) -> 0.0068030564 | G40: =E40/SUM($E$16:$E$58) -> 0.0030311696 | H40: =(1-$B$7) *G40 -> 0.0030311666 | I40: =B40*LN(H40) -> -46.390462 | M40: pvalue | N40: =_xlfn.CHISQ.DIST.RT(N38,N39) -> 9.2939155e-12
A41: 25 | B41: 6 | C41: =C40*($B$1+A40)/(A41*($B$2+1)) -> 0.0027608316 | D41: =C40*($B$3+A40)/(A41*($B$4+1)) -> 0.0029351119 | E41: =C41*(1 - $B$5) + D41*$B$5 -> 0.0028254486 | F41: =IF(MOD(A41,2) = 0, E41*B$6, E41) -> 0.0028254486 | G41: =E41/SUM($E$16:$E$58) -> 0.0027415509 | H41: =(1-$B$7) *G41 -> 0.0027415481 | I41: =B41*LN(H41) -> -35.395395
A42: 26 | B42: 3 | C42: =C41*($B$1+A41)/(A42*($B$2+1)) -> 0.0024992287 | D42: =C41*($B$3+A41)/(A42*($B$4+1)) -> 0.0026582499 | E42: =C42*(1 - $B$5) + D42*$B$5 -> 0.0025581882 | F42: =IF(MOD(A42,2) = 0, E42*B$6, E42) -> 0.0055710264 | G42: =E42/SUM($E$16:$E$58) -> 0.0024822264 | H42: =(1-$B$7) *G42 -> 0.0024822239 | I42: =B42*LN(H42) -> -17.995801 | M42: LRT vs Original
A43: 27 | B43: 9 | C43: =C42*($B$1+A42)/(A43*($B$2+1)) -> 0.0022646597 | D43: =C42*($B$3+A42)/(A43*($B$4+1)) -> 0.0024098063 | E43: =C43*(1 - $B$5) + D43*$B$5 -> 0.0023184749 | F43: =IF(MOD(A43,2) = 0, E43*B$6, E43) -> 0.0023184749 | G43: =E43/SUM($E$16:$E$58) -> 0.0022496311 | H43: =(1-$B$7) *G43 -> 0.0022496288 | I43: =B43*LN(H43) -> -54.87291 | M43: chisq | N43: =2 * (B8 - 'NBD fit (bad)'!B3) -> 4545.2508
A44: 28 | B44: 5 | C44: =C43*($B$1+A43)/(A44*($B$2+1)) -> 0.002053996 | D44: =C43*($B$3+A43)/(A44*($B$4+1)) -> 0.0021865238 | E44: =C44*(1 - $B$5) + D44*$B$5 -> 0.0021031326 | F44: =IF(MOD(A44,2) = 0, E44*B$6, E44) -> 0.0045800413 | G44: =E44/SUM($E$16:$E$58) -> 0.0020406831 | H44: =(1-$B$7) *G44 -> 0.0020406811 | I44: =B44*LN(H44) -> -30.972358 | M44: df | N44: =4 - 2 -> 2
A45: 29 | B45: 4 | C45: =C44*($B$1+A44)/(A45*($B$2+1)) -> 0.0018645243 | D45: =C44*($B$3+A44)/(A45*($B$4+1)) -> 0.001985572 | E45: =C45*(1 - $B$5) + D45*$B$5 -> 0.0019094045 | F45: =IF(MOD(A45,2) = 0, E45*B$6, E45) -> 0.0019094045 | G45: =E45/SUM($E$16:$E$58) -> 0.0018527074 | H45: =(1-$B$7) *G45 -> 0.0018527056 | I45: =B45*LN(H45) -> -25.164433 | M45: pvalue | N45: =_xlfn.CHISQ.DIST.RT(N43,N44) -> 0
A46: 30 | B46: 7 | C46: =C45*($B$1+A45)/(A46*($B$2+1)) -> 0.0016938822 | D46: =C45*($B$3+A45)/(A46*($B$4+1)) -> 0.0018044823 | E46: =C46*(1 - $B$5) + D46*$B$5 -> 0.0017348888 | F46: =IF(MOD(A46,2) = 0, E46*B$6, E46) -> 0.0037781081 | G46: =E46/SUM($E$16:$E$58) -> 0.0016833738 | H46: =(1-$B$7) *G46 -> 0.0016833721 | I46: =B46*LN(H46) -> -44.708694
A47: 31 | B47: 5 | C47: =C46*($B$1+A46)/(A47*($B$2+1)) -> 0.0015400062 | D47: =C46*($B$3+A46)/(A47*($B$4+1)) -> 0.0016410948 | E47: =C47*(1 - $B$5) + D47*$B$5 -> 0.0015774863 | F47: =IF(MOD(A47,2) = 0, E47*B$6, E47) -> 0.0015774863 | G47: =E47/SUM($E$16:$E$58) -> 0.0015306451 | H47: =(1-$B$7) *G47 -> 0.0015306435 | I47: =B47*LN(H47) -> -32.410335
A48: 32 | B48: 3 | C48: =C47*($B$1+A47)/(A48*($B$2+1)) -> 0.0014010879 | D48: =C47*($B$3+A47)/(A48*($B$4+1)) -> 0.0014935138 | E48: =C48*(1 - $B$5) + D48*$B$5 -> 0.0014353562 | F48: =IF(MOD(A48,2) = 0, E48*B$6, E48) -> 0.0031258088 | G48: =E48/SUM($E$16:$E$58) -> 0.0013927353 | H48: =(1-$B$7) *G48 -> 0.0013927339 | I48: =B48*LN(H48) -> -19.72946
A49: 33 | B49: 3 | C49: =C48*($B$1+A48)/(A49*($B$2+1)) -> 0.0012755378 | D49: =C48*($B$3+A48)/(A49*($B$4+1)) -> 0.001360071 | E49: =C49*(1 - $B$5) + D49*$B$5 -> 0.0013068797 | F49: =IF(MOD(A49,2) = 0, E49*B$6, E49) -> 0.0013068797 | G49: =E49/SUM($E$16:$E$58) -> 0.0012680738 | H49: =(1-$B$7) *G49 -> 0.0012680725 | I49: =B49*LN(H49) -> -20.010772
A50: 34 | B50: 2 | C50: =C49*($B$1+A49)/(A50*($B$2+1)) -> 0.0011619552 | D50: =C49*($B$3+A49)/(A50*($B$4+1)) -> 0.0012392946 | E50: =C50*(1 - $B$5) + D50*$B$5 -> 0.0011906299 | F50: =IF(MOD(A50,2) = 0, E50*B$6, E50) -> 0.0025928626 | G50: =E50/SUM($E$16:$E$58) -> 0.0011552758 | H50: =(1-$B$7) *G50 -> 0.0011552747 | I50: =B50*LN(H50) -> -13.526834
A51: 35 | B51: 2 | C51: =C50*($B$1+A50)/(A51*($B$2+1)) -> 0.0010591026 | D51: =C50*($B$3+A50)/(A51*($B$4+1)) -> 0.0011298825 | E51: =C51*(1 - $B$5) + D51*$B$5 -> 0.0010853453 | F51: =IF(MOD(A51,2) = 0, E51*B$6, E51) -> 0.0010853453 | G51: =E51/SUM($E$16:$E$58) -> 0.0010531175 | H51: =(1-$B$7) *G51 -> 0.0010531164 | I51: =B51*LN(H51) -> -13.712003
A52: 36 | B52: 3 | C52: =C51*($B$1+A51)/(A52*($B$2+1)) -> 0.00096588441 | D52: =C51*($B$3+A51)/(A52*($B$4+1)) -> 0.0010306809 | E52: =C52*(1 - $B$5) + D52*$B$5 -> 0.00098990865 | F52: =IF(MOD(A52,2) = 0, E52*B$6, E52) -> 0.0021557473 | G52: =E52/SUM($E$16:$E$58) -> 0.00096051472 | H52: =(1-$B$7) *G52 -> 0.00096051376 | I52: =B52*LN(H52) -> -20.844127
...
